Workbook
Name _xlchart.v1.43: Master!$C$144:$G$144
Name _xlchart.v1.64: DynamicPlotData!$B$2:$F$2
Name _xlchart.v1.48: DynamicPlotData!$B$2:$F$2
Name _xlchart.v1.31: Master!$C$27:$G$27
Name _xlchart.v1.60: Master!$C$145:$G$145
Name _xlchart.v1.30: Master!$C$147:$G$147
Name _xlchart.v1.55: Master!$C$27:$G$27
Name _xlchart.v1.20: Master!$C$145:$G$145
Name _xlchart.v1.41: Master!$C$142:$G$142
Name _xlchart.v1.57: Master!$C$142:$G$142
Name _xlchart.v1.19: Master!$C$144:$G$144
Name _xlchart.v1.50: Master!$C$143:$G$143
Name _xlchart.v1.11: Master!$C$144:$G$144
Name _xlchart.v1.38: Master!$C$147:$G$147
Name _xlchart.v1.34: Master!$C$143:$G$143
Name _xlchart.v1.36: Master!$C$145:$G$145
Name _xlchart.v1.25: Master!$C$142:$G$142
Name _xlchart.v1.26: Master!$C$143:$G$143
Name _xlchart.v1.14: Master!$C$147:$G$147
Name _xlchart.v1.61: Master!$C$146:$G$146
Name _xlchart.v1.51: Master!$C$144:$G$144
Name _xlchart.v1.3: Master!$C$144:$G$144
Name _xlchart.v1.58: Master!$C$143:$G$143
Name _xlchart.v1.40: DynamicPlotData!$B$2:$F$2
Name _xlchart.v1.7: Master!$C$27:$G$27
Name _xlchart.v1.42: Master!$C$143:$G$143
Name _xlchart.v1.5: Master!$C$146:$G$146
Name _xlchart.v1.32: DynamicPlotData!$B$2:$F$2
Name _xlchart.v1.53: Master!$C$146:$G$146
Name _xlchart.v1.22: Master!$C$147:$G$147
Name _xlchart.v1.68: Master!$C$145:$G$145
Name _xlchart.v1.15: Master!$C$27:$G$27
Name _xlchart.v1.37: Master!$C$146:$G$146
Name _xlchart.v1.18: Master!$C$143:$G$143
Name _xlchart.v1.65: Master!$C$142:$G$142
Name _xlchart.v1.71: Master!$C$27:$G$27
Name _xlchart.v1.56: DynamicPlotData!$B$2:$F$2
Name _xlchart.v1.17: Master!$C$142:$G$142
Name _xlchart.v1.8: DynamicPlotData!$B$2:$F$2
Name _xlchart.v1.45: Master!$C$146:$G$146
Name _xlchart.v1.63: Master!$C$27:$G$27
Name _xlchart.v1.46: Master!$C$147:$G$147
Name _xlchart.v1.4: Master!$C$145:$G$145
Name _xlchart.v1.70: Master!$C$147:$G$147
Name _xlchart.v1.12: Master!$C$145:$G$145
Name _xlchart.v1.47: Master!$C$27:$G$27
Name _xlchart.v1.0: DynamicPlotData!$B$2:$F$2
Name _xlchart.v1.67: Master!$C$144:$G$144
Name _xlchart.v1.52: Master!$C$145:$G$145
Name _xlchart.v1.27: Master!$C$144:$G$144
Name _xlchart.v1.39: Master!$C$27:$G$27
Name _xlchart.v1.24: DynamicPlotData!$B$2:$F$2
Name _xlchart.v1.21: Master!$C$146:$G$146
Name _xlchart.v1.69: Master!$C$146:$G$146
Name _xlchart.v1.54: Master!$C$147:$G$147
Name _xlchart.v1.35: Master!$C$144:$G$144
Name _xlchart.v1.10: Master!$C$143:$G$143
Name _xlchart.v1.49: Master!$C$142:$G$142
Name _xlchart.v1.16: DynamicPlotData!$B$2:$F$2
Name _xlchart.v1.59: Master!$C$144:$G$144

Sheet ReadMe-Directions
A1: Immersive Model for Lake Mead based on the Principle of Divide Reservoir Inflow
A3: OVERVIEW
A4: The purpose of this tool is to give collaborators the opportunity to immerse in and personify water user roles for a Lake Mead model based on the principle of divide reservoir inflow. The process is: A) Divide reservoir inflow, B) Subtract evaporation, and C) Users withdraw and conserve within their available water, others choices, and real-time discussion of choices. We see uses of the tool for two purposes:
A5: 1) As researchers we want to learn: Why basin partners choose assumptions and how extreme; Why and how basin partners articulate their risk of uncertain future water supply and manage their vulnerability; and Which new insights they take from a model session.
A6: 2) Provoke thought and discussion to:
B7: a) Stabilize and recover reservoir storage under conditions of low storage and low inflow, and
B8: b) Give users more autonomy to manage their conflicting vulnerabilities to water shortages.
A10: KEY IDEAS
A12: 1) | B12: There is broad agreement in Reclamation's modeling methods that Colorado River flows will be more volative, declining, and have longer-lasting periods of flow.
A14: 2) | B14: Lake Mead water level is the sum of the protection elevation and each user’s available water.
A16: 3) | B16: Each user manages all their available water not just prior conserved water.
A18: 4) | B18: Tribal Nations of the Lower Basin manage their own settled water rights (82.2% is from Arizona, 1.3% is from Nevada, 16.4% is from California).
A20: See Let's Start Guide for visualizations of Key Ideas --- | E20: Here
A22: REQUIREMENTS
A23: Session Guide: 1 person to setup in Google Sheets (see Setup below), invite participants, and organize play.
A24: Number of People: 2 or more (Session guide may also participate).
A25: Time: 1 to 3 hours.
A26: Software: Session Guide has a Google Account.
A28: DIRECTIONS to GUIDE a MODEL SESSION
A29: Setup
A30: 1 | B30: Download this Excel file (done :)
A31: 2 | B31: Move this Excel file to your Google Drive. Open as a Google Sheet. In the Upper Right, click the Share button. Add emails and set permissions so other participants can access the Google Sheets. Or copy and share the sheet's URL.
A32: 3 | B32: Open the Versions Worksheet to see updates.
A33: 4 | B33: Duplicate the Master Worksheet to work on in this session and save a blank version for later use.
A34: 5 | B34: Invite 1 or more other people to join the Google Sheet.
B35: a. In the upper right of the Google Sheet, click the Share button.
B36: b. Add emails, and set permissions so players can access the Google Sheet. Or copy and share the sheet's URL.
A37: Play
A38: 1 | B38: On the Master Worksheet, scroll down Column A. Participants enter values in rows with Blue text.
B39: a. For example, in Rows 4-10, particants select a User, articulate the User's vulnerability to water shortages, and define a strategy to manage vulnerability. If fewer than 6 participants, participants select multiple users.
A40: 2 | B40: Enter the Lake Mead starting storage in Cell B19. Find the current storage at https://www.usbr.gov/lc/region/g4000/hourly/mead-elv.html
A41: 3 | B41: In Cell B20, the Reclamation user sets the elevation for the protection zone - Lake Mead will never fall below this level.
A42: 4 | B42: In Cell B21, enter the total Water Conservation Account (Intentionally Created Surplus) Balance. This value includes California, Arizona, Nevada, and Mexico.
A43: 5 | B43: Enter the Lake Mead Inflow for Year 1 in Cell C28. Cells below will populate.
A44: 6 | B44: Participant Dashboards and Rows with Blue Text (Rows 62 to 121): Participants enter their choices to withdraw, conserve, and trade water in response to their available water, others choices, and the real-time discussion by participants.
A45: 7 | B45: Move to Year 2 (Column D). Enter Lake Powell natural flow in Cell D28.
A47: Additional Information and Help
A48: A. | B48: Find linked help for each row in Column N.
A49: B. | B49: View the Master-Plots worksheet to compare entries to current operations (Law of the River). Current operations are calculated on the Master-LawOfRiver Worksheet. [[This feature is not yet enabled]]
A51: LETS START (visual directions as pdf)
...

Sheet Versions
A1: Date Implimented | B1: Version | C1: Changes | D1: Hours | E1: Implemented By | F1: Suggested By | G1: Date Suggested | I1: To Do List | J1: Suggested By | K1: Date Suggested
A2: 45413 | B2: 1.0 | C2: Copied spreadsheet from Colorado River Basin Water Accounts | D2: 0.3 | E2: Rosenberg | F2: Rosenberg
A3: 45604 | B3: 1.1 | C3: Update for Lake Mead. Water Users, Remove Powell, Modify water balance, Update directions | D3: 4 | E3: Rosenberg | F3: Rosenberg
A4: 45611 | B4: 1.2 | C4: Add Tribal water account | D4: 0.3 | E4: Rosenberg | F4: Rosenberg
A5: 45622 | B5: 1.3 | C5: Start documenting model with instructions and user guide. | D5: 4 | E5: Rosenberg | F5: Rosenberg
A6: 45666 | B6: 1.3.1 | C6: Update text in ReadMe-Directions and Model Guide | D6: 3 | E6: Rosenberg | F6: Rosenberg
A7: 45670 | B7: 1.4 | C7: Add parameter to specify how much of allocation for Tribes of the Lower Basin comes from California vs. Arizona | D7: 0.5 | E7: Rosenberg | F7: Rosenberg
A8: 45671 | B8: 1.4.1 | C8: Document Tribal parameter in Users Guide | D8: 0.5 | E8: Rosenberg | F8: Rosenberg
A9: 45681 | B9: 1.4.2 | C9: Add images of key ideas to ReadMe | D9: 0.25 | E9: Rosenberg | F9: Rosenberg
A10: 45681 | B10: 1.4.3 | C10: Add recent water use in Model Guide | D10: 1 | E10: Rosenberg | F10: CEE 6490 students; Akbar | G10: 45678
A11: 45762 | B11: 1.5 | C11: Add extreme low Lake Mead inflow hydrologic scenarios | D11: 12 | E11: Myers | F11: Collaborators in model session | G11: 45702
A12: 45798 | B12: 1.6 | C12: Add Tribal Nations in Lake Mead inflow allocation | D12: 6 | E12: Myers | F12: Collaborators in model session; Rosenberg | G12: 45702
A13: 45827 | B13: 1.6.1 | C13: Add new images for Tribal allocation | D13: 5 | E13: Myers | F13: Collaborators in model session; Rosenberg | G13: 45702
A14: 45831 | B14: 1.7 | C14: Add new row for unit price | D14: 1.5 | E14: Myers | F14: Rosenberg | G14: 45813
A15: 45895 | B15: 1.8 | C15: Fixed errors in OFFSETs at summary at bottom of the master sheet | D15: 0.5 | E15: Rosenberg
A16: 45895 | B16: 1.9 | C16: Fixed ICS starting storage so that when there is less storage above the Reclamation protection volume than ICS balances, the model prorates the user's starting storages. When there is more available water above the protection volume than ICS balances, each user gets their ICS balance and Tribal Nations get the remainder | D16: 1 | E16: Rosenberg
A17: 45993 | B17: 1.9.1 | C17: Added starting available water row | D17: 0.5 | E17: Myers | F17: Rosenberg | G17: 45980

Sheet Master
A1: ='ReadMe-Directions'!A1 -> Immersive Model for Lake Mead based on the Principle of Divide Reservoir Inflow
A2: Participants enter values in row blocks with bold blue instructions. See help in Column N.
A3: 1. Assign participants and define strategies in Cells A5 to C10 (Up to 5 players): | N3: HELP, CONTEXT, and SUGGESTIONS
A4: User | B4: Person | C4: Vulnerability and Strategy to Manage Vulnerability | N4: Help assign parties and specify strategies
A5: Reclamation - Protect Zone | B5: Sam | C5: Set Lake Mead Protection Elevation of 1,020 feet as defined in the Lower Basin Drought Contingency Plan (USBR, 2019). Lake Mead will not fall below this level. Lower the protection elevation to allocate more active storage to other users.
A6: California | B6: Maddie | C6: Continue mandatory conservation and cutback from 4.4 maf per year as Lake Mead level declines from 1,090 to 1,025 feet (USBR, 2019). See cutback schedule in MandatoryConservation sheet. These values exclude 0.95 maf per year of use by First Nations in the Lower Basin
A7: Arizona | B7: Talha | C7: Continue mandatory conservation and cutback from 2.8 maf per year as Lake Mead level declines from 1,090 to 1,025 feet (USBR, 2019). See cutback schedule in MandatoryConservation sheet. These values exclude 0.95 maf per year of use by First Nations in the Lower Basin. Cut back an addition amount per year to represent the 500-Plus Plan (Allhands, 2021). Buy water to reduce mandatory conservation. Save some water for future years.
A8: Nevada | B8: Sam | C8: Continue mandatory conservation and cutback from 0.3 maf per year as Lake Mead level declines from 1,090 to 1,025 feet (USBR, 2019). See cutback schedule in MandatoryConservation sheet. These values exclude 0.95 maf per year of use by First Nations in the Lower Basin. Cut back an addition amount per year to represent the 500-Plus Plan (Allhands, 2021). Buy water to reduce mandatory conservation. Save some water for future years.
A9: Mexico | B9: Lan | C9: Continue mandatory conservation and cutback from 1.5 maf per year as Lake Mead levels decline (IBWC, 2021). See MandatoryConservation sheet. Conserve more water beyond mandatory targets. Lease water to get money for non-water projects.
A10: Tribal Nations of the Lower Basin | B10: Maddie | C10: Save water for future use.
A12: 1A. Explain Cell Types | B12: Physical watershed data | N12: Help explain cell types
B13: Individual decision
B14: Joint decision
B15: Calculated cell
A17: 1B. Make Lake Mead Assumptions | B17: Elevation (feet) | C17: Volume (maf) | N17: Help make assumptions
A18: Evaporation rate (feet/year) | B18: 6 | N18: Help evaporation rate
A19: Start storage (million acre feet) | B19: 1025 | C19: =VLOOKUP(B19,'Mead-Elevation-Area'!$A$5:$B$676,2)/1000000 -> 5.981122 | D19: Dec, 2024 | F19: https://www.usbr.gov/lc/region/g4000/hourly/mead-elv.html | N19: Help start storage
A20: =" Set "&A5 -> Set Reclamation - Protect Zone | B20: 1020 | C20: =VLOOKUP(IF(B20="",895,B20),'Mead-Elevation-Area'!$A$5:$B$689,2)/1000000 -> 5.664593 | N20: Help protect elevation
A21: Storage above Protect Zone | C21: =C19-C20 -> 0.316529 | N21: Help storage above protect zone
A22: Water Conservation Program (ICS) Total Balance | C22: 3.534 | D22: End of 2023 | N22: Help Water Conservation Program Total Balance
A23: Remaining Storage above Protect and ICS Balances (maf) | C23: =C21-C22 -> -3.217471 | N23: Help remaining storage above protect and ICS
A24: Percent of Tribal Nation water in California | B24: =TribalWater!H7 -> 0.16438106 | N24: Help percent of Tribal Nation water in CA
A25: Percent of Tribal Nation water in Arizona | B25: =1-B24 -> 0.83561894 | N25: Help percent of Tribal Nation water in AZ
A27: Water Budget Component (maf unless noted) | B27: Initialize | C27: Year 1 | D27: Year 2 | E27: Year 3 | F27: Year 4 | G27: Year 5 | H27: Year 6 | I27: Year 7 | J27: Year 8 | K27: Year 9 | L27: Year 10 | M27: Total | N27: =N3 -> HELP, CONTEXT, and SUGGESTIONS
A28: 2. Specify Lake Mead Inflow | C28: 3.8 | D28: 6.3 | N28: Help specify Lake Mead inflow
A29: Intervening (Grand Canyon) inflow | C29: =IF(C$28<>"",0.8,"") -> 0.8 | D29: =IF(D$28<>"",0.8,"") -> 0.8 | E29: =IF(E$28<>"",0.8,"") | F29: =IF(F$28<>"",0.8,"") | G29: =IF(G$28<>"",0.8,"") | H29: =IF(H$28<>"",0.8,"") | I29: =IF(I$28<>"",0.8,"") | J29: =IF(J$28<>"",0.8,"") | ... L29: =IF(L$28<>"",0.8,"") | N29: Help intervening Grand Canyon inflow
A30: Mead to Imperial Dam intervening inflow | C30: =IF(C$28<>"",0.2,"") -> 0.2 | D30: =IF(D$28<>"",0.2,"") -> 0.2 | E30: =IF(E$28<>"",0.2,"") | F30: =IF(F$28<>"",0.2,"") | G30: =IF(G$28<>"",0.2,"") | H30: =IF(H$28<>"",0.2,"") | I30: =IF(I$28<>"",0.2,"") | J30: =IF(J$28<>"",0.2,"") | ... L30: =IF(L$28<>"",0.2,"") | N30: Help Mead to Imperial intervening flow
A31: Havasu / Parker evaporation and ET | C31: =IF(C$28<>"",0.6,"") -> 0.6 | D31: =IF(D$28<>"",0.6,"") -> 0.6 | E31: =IF(E$28<>"",0.6,"") | F31: =IF(F$28<>"",0.6,"") | G31: =IF(G$28<>"",0.6,"") | H31: =IF(H$28<>"",0.6,"") | I31: =IF(I$28<>"",0.6,"") | J31: =IF(J$28<>"",0.6,"") | ... L31: =IF(L$28<>"",0.6,"") | N31: Help Havasu/Parker evap. and ET
A32: Beginning of Year Lake Mead
A33: Storage (maf) | C33: =IF(C$28<>"",IF(COLUMN(C28)=COLUMN($C28),$C$19,B149),"") -> 5.981122 | D33: =IF(D$28<>"",IF(COLUMN(D28)=COLUMN($C28),$C$19,C149),"") -> 5.6315327 | E33: =IF(E$28<>"",IF(COLUMN(E28)=COLUMN($C28),$C$19,D149),"") | F33: =IF(F$28<>"",IF(COLUMN(F28)=COLUMN($C28),$C$19,E149),"") | G33: =IF(G$28<>"",IF(COLUMN(G28)=COLUMN($C28),$C$19,F149),"")
A34: Elevation (feet) | C34: =IF(C$28<>"",IF(COLUMN(C29)=COLUMN($C29),$B$19,B150),"") -> 1025 | D34: =IF(D$28<>"",IF(COLUMN(D29)=COLUMN($C29),$B$19,C150),"") -> 1019 | E34: =IF(E$28<>"",IF(COLUMN(E29)=COLUMN($C29),$B$19,D150),"") | F34: =IF(F$28<>"",IF(COLUMN(F29)=COLUMN($C29),$B$19,E150),"") | G34: =IF(G$28<>"",IF(COLUMN(G29)=COLUMN($C29),$B$19,F150),"")
A35: 3. Split storage (Year 1 only; Current ICS Account Balances). | H35: =IF(H$28<>"",G149,"") | I35: =IF(I$28<>"",H148,"") | J35: =IF(J$28<>"",I148,"") | K35: =IF(K$28<>"",J148,"") | L35: =IF(L$28<>"",K148,"") | N35: Help split reservoir storage
A36: =IF(A5="",""," "&A5&" Balance") -> Reclamation - Protect Zone Balance | B36: =C20 -> 5.664593 | C36: =IF(OR(C$28="",$A36=""),"",B36) -> 5.664593 | D36: =IF(OR(D$28="",$A36=""),"",C142) -> 5.614593 | E36: =IF(OR(E$28="",$A36=""),"",D142) | F36: =IF(OR(F$28="",$A36=""),"",E142) | G36: =IF(OR(G$28="",$A36=""),"",F142) | H36: =IF(OR(H$28="",$A36=""),"",G142) | I36: =IF(OR(I$28="",$A36=""),"",H142) | J36: =IF(OR(J$28="",$A36=""),"",I142) | K36: =IF(OR(K$28="",$A36=""),"",J142) | L36: =IF(OR(L$28="",$A36=""),"",K142)
A37: =IF(A6="",""," "&A6&" Balance") -> California Balance | B37: =1.662*IF(C23>0,1,(C21/C22)) -> 0.14885999 | C37: =IF(OR(C$28="",$A37=""),"",B37) -> 0.14885999 | D37: =IF(OR(D$28="",$A37=""),"",C143) -> 0.028264811 | E37: =IF(OR(E$28="",$A37=""),"",D143) | F37: =IF(OR(F$28="",$A37=""),"",E143) | G37: =IF(OR(G$28="",$A37=""),"",F143) | H37: =IF(OR(H$28="",$A37=""),"",G143) | I37: =IF(OR(I$28="",$A37=""),"",H143) | J37: =IF(OR(J$28="",$A37=""),"",I143) | K37: =IF(OR(K$28="",$A37=""),"",J143) | L37: =IF(OR(L$28="",$A37=""),"",K143)
A38: =IF(A7="",""," "&A7&" Balance") -> Arizona Balance | B38: =0.711*IF(C23>0,1,C21/C22) -> 0.06368198 | C38: =IF(OR(C$28="",$A38=""),"",B38) -> 0.06368198 | D38: =IF(OR(D$28="",$A38=""),"",C144) -> 0 | E38: =IF(OR(E$28="",$A38=""),"",D144) | F38: =IF(OR(F$28="",$A38=""),"",E144) | G38: =IF(OR(G$28="",$A38=""),"",F144) | H38: =IF(OR(H$28="",$A38=""),"",G144) | I38: =IF(OR(I$28="",$A38=""),"",H144) | J38: =IF(OR(J$28="",$A38=""),"",I144) | K38: =IF(OR(K$28="",$A38=""),"",J144) | L38: =IF(OR(L$28="",$A38=""),"",K144)
A39: =IF(A8="",""," "&A8&" Balance") -> Nevada Balance | B39: =0.9556*IF(C23>0,1,C21/C22) -> 0.085590015 | C39: =IF(OR(C$28="",$A39=""),"",B39) -> 0.085590015 | D39: =IF(OR(D$28="",$A39=""),"",C145) -> 0.0048325194 | E39: =IF(OR(E$28="",$A39=""),"",D145) | F39: =IF(OR(F$28="",$A39=""),"",E145) | G39: =IF(OR(G$28="",$A39=""),"",F145) | H39: =IF(OR(H$28="",$A39=""),"",G145) | I39: =IF(OR(I$28="",$A39=""),"",H145) | J39: =IF(OR(J$28="",$A39=""),"",I145) | K39: =IF(OR(K$28="",$A39=""),"",J145) | L39: =IF(OR(L$28="",$A39=""),"",K145)
A40: =IF(A9="",""," "&A9&" Balance") -> Mexico Balance | B40: =0.211*IF(C23>0,1,C21/C22) -> 0.018898591 | C40: =IF(OR(C$28="",$A40=""),"",B40) -> 0.018898591 | D40: =IF(OR(D$28="",$A40=""),"",C146) -> 0.020330212 | E40: =IF(OR(E$28="",$A40=""),"",D146) | F40: =IF(OR(F$28="",$A40=""),"",E146) | G40: =IF(OR(G$28="",$A40=""),"",F146) | H40: =IF(OR(H$28="",$A40=""),"",G146) | I40: =IF(OR(I$28="",$A40=""),"",H146) | J40: =IF(OR(J$28="",$A40=""),"",I146) | K40: =IF(OR(K$28="",$A40=""),"",J146) | L40: =IF(OR(L$28="",$A40=""),"",K146)
A41: =IF(A10="",""," "&A10&" Balance") -> Tribal Nations of the Lower Basin Balance | B41: =IF(C23>0,C23,0) -> 0 | C41: =IF(OR(C$28="",$A41=""),"",B41) -> 0 | D41: =IF(OR(D$28="",$A41=""),"",C147) -> -0.036487866 | E41: =IF(OR(E$28="",$A41=""),"",D147) | F41: =IF(OR(F$28="",$A41=""),"",E147) | G41: =IF(OR(G$28="",$A41=""),"",F147) | H41: =IF(OR(H$28="",$A41=""),"",G147) | I41: =IF(OR(I$28="",$A41=""),"",H147) | J41: =IF(OR(J$28="",$A41=""),"",I147) | K41: =IF(OR(K$28="",$A41=""),"",J147) | L41: =IF(OR(L$28="",$A41=""),"",K147)
A42: Beginning of year reservoir storage | N42: Help begin of year storage
A43: Powell | C43: =IF(C$28<>"",IF(COLUMN(C27)=COLUMN($C27),$B$19,#REF!),"") -> 1025 | D43: =IF(D$28<>"",IF(COLUMN(D27)=COLUMN($C27),$B$19,#REF!),"") -> #REF! | E43: =IF(E$28<>"",IF(COLUMN(E27)=COLUMN($C27),$B$19,#REF!),"") | F43: =IF(F$28<>"",IF(COLUMN(F27)=COLUMN($C27),$B$19,#REF!),"") | G43: =IF(G$28<>"",IF(COLUMN(G27)=COLUMN($C27),$B$19,#REF!),"") | H43: =IF(H$28<>"",IF(COLUMN(H27)=COLUMN($C27),$B$19,#REF!),"") | I43: =IF(I$28<>"",IF(COLUMN(I27)=COLUMN($C27),$B$19,#REF!),"") | J43: =IF(J$28<>"",IF(COLUMN(J27)=COLUMN($C27),$B$19,#REF!),"") | ... L43: =IF(L$28<>"",IF(COLUMN(L27)=COLUMN($C27),$B$19,#REF!),"")
...

Sheet DivideInflow
A1: Use March 2024 Lower Basin Alternative shortages to divide inflow among water users
A2: A transformation uses percentage splits of shortages to specify percentage splits of Lake Mead Inflow.
A3: Buschatzke, T., Hamby, J. B., and Entsminger, J. (2024). "Lower Basin Alternative for the Post-2026 Coordinated Operation of the Colorado River Basin." https://www.snwa.com/assets/pdf/lower-basin-alternative-letter-march2024.pdf [Accessed on: August 14, 2024].
B5: Total Shortage (maf per year) | C5: Arizona | D5: Nevada | E5: California | F5: Mexico | G5: Total | I5: Based Off of 2024 Lower Basin Shortage Agreement: Tribal Nations Included in Lake Mead Inflow Allocation
B6: As Percent of Total Shortage | I6: Row | J6: Total Shortage (maf per year) [A] | K6: Lake Mead Inflow (maf per year) [B] | L6: Share of Lake Mead Inflow (maf per year) | R6: Percentage of Lake Mead Inflow
B7: 0 | C7: 0 | D7: 0 | E7: 0 | F7: 0 | G7: =SUM(C7:F7) -> 0 | L7: Arizona [C] | M7: Nevada [D] | N7: California [E] | O7: Mexico [F] | P7: Tribal Nations [T] | Q7: Total [G] | R7: Arizona [H] | S7: Nevada [I] | T7: California [J] | U7: Mexico [K] | V7: Tribal Nations [T] | W7: Total [L]
B8: 0.0 to 0.3 | C8: 0.8 | D8: 0.0333 | E8: 0 | F8: 0.1667 | G8: =SUM(C8:F8) -> 1 | I8: [1] | J8: 0 | K8: 9 | L8: =L22-(P8*TribalWater!$H$6) -> 2.016866 | M8: =M22-(P8*TribalWater!$H$5) -> 0.287466 | N8: =N22-(P8*TribalWater!$H$7) -> 4.243478 | O8: =O22 -> 1.5 | P8: =TribalWater!$G$8/1000000 -> 0.95219 | Q8: =SUM(L8:P8) -> 9 | R8: =L8/$K8 -> 0.22409622 | S8: =M8/$K8 -> 0.031940667 | T8: =N8/$K8 -> 0.47149756 | U8: =O8/$K8 -> 0.16666667 | V8: =P8/$K8 -> 0.10579889 | W8: =SUM(R8:V8) -> 1 | X8: Historical allocations
B9: 0.3 to 1.5 | C9: 0.4333 | D9: 0.0333 | E9: 0.3667 | F9: 0.1667 | G9: =SUM(C9:F9) -> 1 | I9: [2] | J9: 0.3 | K9: 8.7 | L9: =L23-(P9*TribalWater!$H$6) -> 1.9129805 | M9: =M23-(P9*TribalWater!$H$5) -> 0.2778938 | N9: =N23-(P9*TribalWater!$H$7) -> 4.1386854 | O9: =U9*K9 -> 1.45 | P9: =V9*K9 -> 0.92045033 | Q9: =SUM(L9:P9) -> 8.70001 | R9: =L9/$K9 -> 0.21988281 | S9: =M9/$K9 -> 0.031941816 | T9: =N9/K9 -> 0.47571097 | U9: 0.16666667 | V9: 0.10579889 | W9: =SUM(R9:V9) -> 1.0000011
B10: As Volume (maf per year) | I10: [3] | J10: 0.4 | K10: 8.6 | L10: =L24-(P10*TribalWater!$H$6) -> 1.878352 | M10: =M24-(P10*TribalWater!$H$5) -> 0.27470307 | N10: =N24-(P10*TribalWater!$H$7) -> 4.1037545 | O10: =U10*K10 -> 1.4333333 | P10: =V10*K10 -> 0.90987044 | Q10: =SUM(L10:P10) -> 8.6000133 | R10: =L10/$K10 -> 0.21841302 | S10: =M10/$K10 -> 0.031942217 | T10: =N10/K10 -> 0.47718076 | U10: 0.16666667 | V10: 0.10579889 | W10: =SUM(R10:V10) -> 1.0000015
B11: 0 | C11: 0 | D11: 0 | E11: 0 | F11: 0 | G11: =SUM(C11:F11) -> 0 | I11: [4] | J11: 1 | K11: 8 | L11: =L25-(P11*TribalWater!$H$6) -> 1.6705809 | M11: =M25-(P11*TribalWater!$H$5) -> 0.25555867 | N11: =N25-(P11*TribalWater!$H$7) -> 3.8941693 | O11: =U11*K11 -> 1.3333333 | P11: =V11*K11 -> 0.84639111 | Q11: =SUM(L11:P11) -> 8.0000333 | R11: =L11/$K11 -> 0.20882261 | S11: =M11/$K11 -> 0.031944833 | T11: =N11/K11 -> 0.48677117 | U11: 0.16666667 | V11: 0.10579889 | W11: =SUM(R11:V11) -> 1.0000042
B12: 0.3 | C12: =$B12*C$9 -> 0.12999 | D12: =$B12*D$9 -> 0.00999 | E12: =$B12*E$9 -> 0.11001 | F12: =$B12*F$9 -> 0.05001 | G12: =SUM(C12:F12) -> 0.3 | I12: [5] | J12: 1.5 | K12: 7.5 | L12: =L26-(P12*TribalWater!$H$6) -> 1.4974383 | M12: =M26-(P12*TribalWater!$H$5) -> 0.239605 | N12: =N26-(P12*TribalWater!$H$7) -> 3.719515 | O12: =U12*K12 -> 1.25 | P12: =V12*K12 -> 0.79349167 | Q12: =SUM(L12:P12) -> 7.50005 | R12: =L12/$K12 -> 0.19965844 | S12: =M12/$K12 -> 0.031947333 | T12: =N12/K12 -> 0.49593533 | U12: 0.16666667 | V12: 0.10579889 | W12: =SUM(R12:V12) -> 1.0000067 | X12: Chosen for model Calculations. California has a higher priority.
B13: 0.4 | C13: =$B13*C$9 -> 0.17332 | D13: =$B13*D$9 -> 0.01332 | E13: =$B13*E$9 -> 0.14668 | F13: =$B13*F$9 -> 0.06668 | G13: =SUM(C13:F13) -> 0.4 | I13: [6] | J13: 2.7 | K13: 6.3 | L13: =L27-(P13*TribalWater!$H$6) -> 1.0818962 | M13: =M27-(P13*TribalWater!$H$5) -> 0.2013162 | N13: =N27-(P13*TribalWater!$H$7) -> 3.3003446 | O13: =U13*K13 -> 1.05 | P13: =V13*K13 -> 0.666533 | Q13: =SUM(L13:P13) -> 6.30009 | R13: =L13/$K13 -> 0.17172956 | S13: =M13/$K13 -> 0.031954952 | T13: =N13/K13 -> 0.52386422 | U13: 0.16666667 | V13: 0.10579889 | W13: =SUM(R13:V13) -> 1.0000143
B14: 1 | C14: =$B14*C$9 -> 0.4333 | D14: =$B14*D$9 -> 0.0333 | E14: =$B14*E$9 -> 0.3667 | F14: =$B14*F$9 -> 0.1667 | G14: =SUM(C14:F14) -> 1 | I14: [7] | J14: 4 | K14: 5 | L14: =L28-(P14*TribalWater!$H$6) -> 0.63172556 | M14: =M28-(P14*TribalWater!$H$5) -> 0.15983667 | N14: =N28-(P14*TribalWater!$H$7) -> 2.8462433 | O14: =U14*K14 -> 0.83333333 | P14: =V14*K14 -> 0.52899444 | Q14: =SUM(L14:P14) -> 5.0001333 | R14: =L14/$K14 -> 0.12634511 | S14: =M14/$K14 -> 0.031967333 | T14: =N14/K14 -> 0.56924867 | U14: 0.16666667 | V14: 0.10579889 | W14: =SUM(R14:V14) -> 1.0000267
B15: 1.5 | C15: =$B15*C$9 -> 0.64995 | D15: =$B15*D$9 -> 0.04995 | E15: =$B15*E$9 -> 0.55005 | F15: =$B15*F$9 -> 0.25005 | G15: =SUM(C15:F15) -> 1.5 | I15: [8] | J15: 4.4 | K15: 4.6 | L15: =L29-(P15*TribalWater!$H$6) -> 0.49321151 | M15: =M29-(P15*TribalWater!$H$5) -> 0.14707373 | N15: =N29-(P15*TribalWater!$H$7) -> 2.7065199 | O15: =U15*K15 -> 0.76666667 | P15: =V15*K15 -> 0.48667489 | Q15: =SUM(L15:P15) -> 4.6001467 | R15: =L15/$K15 -> 0.10721989 | S15: =M15/$K15 -> 0.031972551 | T15: =N15/K15 -> 0.58837388 | U15: 0.16666667 | V15: 0.10579889 | W15: =SUM(R15:V15) -> 1.0000319
B16: 1.5 to 2.7 | C16: To be determined | I16: [9] | J16: 5.2 | K16: 3.8 | L16: =L30-(P16*TribalWater!$H$6) -> 0.21618342 | M16: =M30-(P16*TribalWater!$H$5) -> 0.12154787 | N16: =N30-(P16*TribalWater!$H$7) -> 2.4270729 | O16: =U16*K16 -> 0.63333333 | P16: =V16*K16 -> 0.40203578 | Q16: =SUM(L16:P16) -> 3.8001733 | R16: =L16/$K16 -> 0.056890374 | S16: =M16/$K16 -> 0.031986281 | T16: =N16/K16 -> 0.6387034 | U16: 0.16666667 | V16: 0.10579889 | W16: =SUM(R16:V16) -> 1.0000456
I17: [10] | J17: 8 | K17: 1 | L17: =L31-(P17*TribalWater!$H$6) -> 0.17172956 | M17: =M31-(P17*TribalWater!$H$5) -> 0.031954952 | N17: =N31-(P17*TribalWater!$H$7) -> 0.52386422 | O17: =U17*K17 -> 0.16666667 | P17: =V17*K17 -> 0.10579889 | Q17: =SUM(L17:P17) -> 1.0000143 | R17: =L17/$K17 -> 0.17172956 | S17: =M17/$K17 -> 0.031954952 | T17: =N17/K17 -> 0.52386422 | U17: 0.16666667 | V17: 0.10579889 | W17: =SUM(R17:V17) -> 1.0000143
I19: Standardized
I20: Row | J20: Total Shortage (maf per year) [A] | K20: Lake Mead Inflow (maf per year) [B] | L20: Share of Lake Mead Inflow (maf per year) | Q20: Percentage of Lake Mead Inflow
L21: Arizona [C] | M21: Nevada [D] | N21: California [E] | O21: Mexico [F] | P21: Total [G] | Q21: Arizona [H] | R21: Nevada [I] | S21: California [J] | T21: Mexico [K] | U21: Total [L]
I22: [1] | J22: =B11 -> 0 | K22: 9 | L22: 2.8 | M22: 0.3 | N22: 4.4 | O22: 1.5 | P22: =SUM(L22:O22) -> 9 | Q22: =L22/$K22 -> 0.31111111 | R22: =M22/$K22 -> 0.033333333 | S22: =N22/$K22 -> 0.48888889 | T22: =O22/$K22 -> 0.16666667 | U22: =SUM(Q22:T22) -> 1 | V22: Historical allocations
I23: [2] | J23: =B12 -> 0.3 | K23: =K$22-J23 -> 8.7 | L23: =L$22-C12 -> 2.67001 | M23: =M$22-D12 -> 0.29001 | N23: =N$22-E12 -> 4.28999 | O23: =O$22-F12 -> 1.44999 | P23: =SUM(L23:O23) -> 8.7 | Q23: =L23/$K23 -> 0.3068977 | R23: =M23/$K23 -> 0.033334483 | S23: =N23/$K23 -> 0.4931023 | T23: =O23/$K23 -> 0.16666552 | U23: =SUM(Q23:T23) -> 1
I24: [3] | J24: =B13 -> 0.4 | K24: =K$22-J24 -> 8.6 | L24: =L$22-C13 -> 2.62668 | M24: =M$22-D13 -> 0.28668 | N24: =N$22-E13 -> 4.25332 | O24: =O$22-F13 -> 1.43332 | P24: =SUM(L24:O24) -> 8.6 | Q24: =L24/$K24 -> 0.30542791 | R24: =M24/$K24 -> 0.033334884 | S24: =N24/$K24 -> 0.49457209 | T24: =O24/$K24 -> 0.16666512 | U24: =SUM(Q24:T24) -> 1
I25: [4] | J25: =B14 -> 1 | K25: =K$22-J25 -> 8 | L25: =L$22-C14 -> 2.3667 | M25: =M$22-D14 -> 0.2667 | N25: =N$22-E14 -> 4.0333 | O25: =O$22-F14 -> 1.3333 | P25: =SUM(L25:O25) -> 8 | Q25: =L25/$K25 -> 0.2958375 | R25: =M25/$K25 -> 0.0333375 | S25: =N25/$K25 -> 0.5041625 | T25: =O25/$K25 -> 0.1666625 | U25: =SUM(Q25:T25) -> 1
I26: [5] | J26: =B15 -> 1.5 | K26: =K$22-J26 -> 7.5 | L26: =L$22-C15 -> 2.15005 | M26: =M$22-D15 -> 0.25005 | N26: =N$22-E15 -> 3.84995 | O26: =O$22-F15 -> 1.24995 | P26: =SUM(L26:O26) -> 7.5 | Q26: =L26/$K26 -> 0.28667333 | R26: =M26/$K26 -> 0.03334 | S26: =N26/$K26 -> 0.51332667 | T26: =O26/$K26 -> 0.16666 | U26: =SUM(Q26:T26) -> 1
I27: [6] | J27: 2.7 | K27: =K$22-J27 -> 6.3 | L27: =L26-C9*($K26-$K27) -> 1.63009 | M27: =M26-D9*($K26-$K27) -> 0.21009 | N27: =N26-E9*($K26-$K27) -> 3.40991 | O27: =O26-F9*($K26-$K27) -> 1.04991 | P27: =P26-G9*($K26-$K27) -> 6.3 | Q27: =L27/$K27 -> 0.25874444 | R27: =M27/$K27 -> 0.033347619 | S27: =N27/$K27 -> 0.54125556 | T27: =O27/$K27 -> 0.16665238 | U27: =SUM(Q27:T27) -> 1
I28: [7] | J28: =9-K28 -> 4 | K28: 5 | L28: =L26-C9*($K26-$K28) -> 1.0668 | M28: =M26-D9*($K26-$K28) -> 0.1668 | N28: =N26-E9*($K26-$K28) -> 2.9332 | O28: =O26-F9*($K26-$K28) -> 0.8332 | P28: =P26-G9*($K26-$K28) -> 5 | Q28: =L28/$K28 -> 0.21336 | R28: =M28/$K28 -> 0.03336 | S28: =N28/$K28 -> 0.58664 | T28: =O28/$K28 -> 0.16664 | U28: =SUM(Q28:T28) -> 1 | V28: If percentage shares of total shortages for 0.3 to 1.5 maf per year specified in Lower Basin Alternative (2024) continue to total shortages for 1.5 to 2.7 maf per year.
I29: [8] | J29: =9-K29 -> 4.4 | K29: 4.6 | L29: =L26-C9*($K26-$K29) -> 0.89348 | M29: =M26-D9*($K26-$K29) -> 0.15348 | N29: =N26-E9*($K26-$K29) -> 2.78652 | O29: =O26-F9*($K26-$K29) -> 0.76652 | P29: =P26-G9*($K26-$K29) -> 4.6 | Q29: =L29/$K29 -> 0.19423478 | R29: =M29/$K29 -> 0.033365217 | S29: =N29/$K29 -> 0.60576522 | T29: =O29/$K29 -> 0.16663478 | U29: =SUM(Q29:T29) -> 1
I30: [9] | J30: =9-K30 -> 5.2 | K30: 3.8 | L30: =L26-C9*($K26-$K30) -> 0.54684 | M30: =M26-D9*($K26-$K30) -> 0.12684 | N30: =N26-E9*($K26-$K30) -> 2.49316 | O30: =O26-F9*($K26-$K30) -> 0.63316 | P30: =P26-G9*($K26-$K30) -> 3.8 | Q30: =L30/$K30 -> 0.14390526 | R30: =M30/$K30 -> 0.033378947 | S30: =N30/$K30 -> 0.65609474 | T30: =O30/$K30 -> 0.16662105 | U30: =SUM(Q30:T30) -> 1
I31: [10] | J31: 8 | K31: =K$22-J31 -> 1 | L31: =$K31*Q31 -> 0.25874444 | M31: =$K31*R31 -> 0.033347619 | N31: =$K31*S31 -> 0.54125556 | O31: =$K31*T31 -> 0.16665238 | P31: =$K31*U31 -> 1 | Q31: =Q27 -> 0.25874444 | R31: =R27 -> 0.033347619 | S31: =S27 -> 0.54125556 | T31: =T27 -> 0.16665238 | U31: =U27 -> 1 | V31: If percentage shares of total shortages for 0.3 to 1.5 maf per year specified in Lower Basin Alternative (2024) continue to total shortages for 8.0 maf per year.

Sheet TribalWater
A1: This worksheet shows water for Tribal Nations of the Lower Basin (Ten Tribes Partnership, 2018)
A3: Table 5.11-B. Lower Basin Decreed Water Rights and Unresolved Claims
A4: Tribal Nation | B4: State | C4: Decreed Diversion (acre-feet) | D4: Unresolved Diversion Claim (acre-feet) | F4: State | G4: Volume (acre-feet) | H4: Percent
A5: Fort Mojave Indian Tribe | B5: Nevada | C5: 12534 | F5: Nevada | G5: =SUMIFS($C$5:$C$13,$B$5:$B$13,F5) -> 12534 | H5: =G5/G$8 -> 0.013163339
A6: Fort Mojave Indian Tribe | B6: Arizona | C6: 103535 | F6: Arizona | G6: =SUMIFS($C$5:$C$13,$B$5:$B$13,F6) -> 783134 | H6: =G6/G$8 -> 0.8224556
A7: Fort Mojave Indian Tribe | B7: California | C7: 16720 | F7: California | G7: =SUMIFS($C$5:$C$13,$B$5:$B$13,F7) -> 156522 | H7: =G7/G$8 -> 0.16438106
A8: Chemehuevi Indian Tribe | B8: California | C8: 11340 | F8: Total | G8: =SUM(G5:G7) -> 952190 | H8: =G8/G$8 -> 1
A9: Colorado River Indian Tribes | B9: Arizona | C9: 662402
A10: Colorado River Indian Tribes | B10: California | C10: 56846
A11: Quechan Indian Tribe | B11: Arizona | C11: 6350
A12: Quechan Indian Tribe | B12: California | C12: 71616
A13: Cocopah Indian Tribe | B13: Arizona | C13: 10847 | D13: 22928
A14: Total | C14: =SUM(C5:C13) -> 952190 | D14: =SUM(D5:D13) -> 22928
A17: Table 5.11-D. Total Annual Current Tribal Water Use (acre-feet)
A18: Water Use Category | B18: Diversion | C18: Consumptive Use
A19: Irrigatedd Agriculture & Livestock | B19: 769208 | C19: 441381
A20: Domestic, Commercial, Industrial | B20: 15340 | C20: 9017
A21: Environmental, Cultural, Recreation | B21: 2844 | C21: 1698
A22: Transfers, Leases, Exchanges | B22: 13000 | C22: 13000
A23: Total | B23: =SUM(B19:B22) -> 800392 | C23: =SUM(C19:C22) -> 465096

Sheet SplitInflowForPlot
A1: =#REF! -> #REF!
A2: This spreadsheet is used to calculate the split of Lake Powell Natural inflow for different inflow values. The data are visualized on the SplitInflowPlot worksheet.
A3: 1. Assign the Parties, person playing, and each party's strategy in Cells A5 to C10. | N3: HELP, CONTEXT, and SUGGESTIONS
A4: Party | B4: Person | C4: Strategy | N4: Help assign parties
A5: Upper Basin
A6: Lower Basin
A7: Mexico
A8: Colorado River Delta
A9: First Nations
A10: Shared, Reserve
A12: 1A. Explain Cell Types | B12: Physical watershed data | N12: Help explain cell types
B13: Individual party decision
B14: Joint party decision
B15: Calculated cell
A17: 1B. Make reservoir assumptions | B17: Powell | C17: Mead | N17: Help make assumptions
A18: Evaporation rate (feet/year) | B18: 5.73 | C18: 6 | N18: Help evaporation rate
A19: Start storage (million acre feet) | B19: 7.2 | C19: 9 | D19: 9/1/2021 values | N19: Help start storage
A20: Protect elevation (feet) | B20: 3525 | C20: 1020 | N20: Help protect elevation
A21: Storage at protection elevation (maf) | B21: =VLOOKUP(B20,#REF!,2)/1000000 -> #REF! | C21: =VLOOKUP(C20,'Mead-Elevation-Area'!$A$5:$B$689,2)/1000000 -> 5.664593 | N21: Help protect volume
A22: Prior 9 year Lake Powell release (maf) | B22: =78.1 -> 78.1 | N22: Help 9-year prior Powell release
A23: Prior 9-year Paria River flow (maf) | B23: 0.17 | N23: Help 9-year Paria River flow
A24: Delivery to meet 10-year requirement (maf) | B24: =10*(7.5+1.5/2)-B22-B23 -> 4.23 | N24: Help delivery to meet 10-year req.
A25: Upper Basin pre-1922 water rights (maf) | B25: =2.3 - IF(A9<>"",1.06,0) -> 1.24 | N25: Help pre-1922 water rights
A27: Water Budget Component (maf unless noted) | B27: Initialize | C27: Year 1 | D27: Year 2 | E27: Year 3 | F27: Year 4 | G27: Year 5 | H27: Year 6 | I27: Year 7 | J27: Year 8 | K27: Year 9 | L27: Year 10 | M27: Total | N27: =N3 -> HELP, CONTEXT, and SUGGESTIONS
A28: 2. Specify natural inflow to Lake Powell. | C28: 0 | D28: 0 | E28: 0.2 | F28: 2.1 | G28: 3.5 | H28: 6 | I28: 8 | J28: 11.26 | K28: 12.5 | L28: 16 | N28: Help Lake Powell natural inflow
A29: Intervening (Grand Canyon) inflow | C29: 0 | D29: 0.5 | E29: =IF(E$28<>"",0.8,"") -> 0.8 | F29: =IF(F$28<>"",0.8,"") -> 0.8 | G29: =IF(G$28<>"",0.8,"") -> 0.8 | H29: =IF(H$28<>"",0.8,"") -> 0.8 | I29: =IF(I$28<>"",0.8,"") -> 0.8 | J29: =IF(J$28<>"",0.8,"") -> 0.8 | K29: =IF(K$28<>"",0.8,"") -> 0.8 | L29: =IF(L$28<>"",0.8,"") -> 0.8 | N29: Help intervening Grand Canyon inflow
A30: Mead to Imperial Dam intervening inflow | C30: 0 | D30: 0.1 | E30: =IF(E$28<>"",0.2,"") -> 0.2 | F30: =IF(F$28<>"",0.2,"") -> 0.2 | G30: =IF(G$28<>"",0.2,"") -> 0.2 | H30: =IF(H$28<>"",0.2,"") -> 0.2 | I30: =IF(I$28<>"",0.2,"") -> 0.2 | J30: =IF(J$28<>"",0.2,"") -> 0.2 | K30: =IF(K$28<>"",0.2,"") -> 0.2 | L30: =IF(L$28<>"",0.2,"") -> 0.2 | N30: Help Mead to Imperial intervening flow
A31: Havasu / Parker evaporation and ET | C31: =IF(C$28<>"",0.6,"") -> 0.6 | D31: =IF(D$28<>"",0.6,"") -> 0.6 | E31: =IF(E$28<>"",0.6,"") -> 0.6 | F31: =IF(F$28<>"",0.6,"") -> 0.6 | G31: =IF(G$28<>"",0.6,"") -> 0.6 | H31: =IF(H$28<>"",0.6,"") -> 0.6 | I31: =IF(I$28<>"",0.6,"") -> 0.6 | J31: =IF(J$28<>"",0.6,"") -> 0.6 | ... L31: =IF(L$28<>"",0.6,"") -> 0.6 | N31: Help Havasu/Parker evap. and ET
A32: Reservoir Storage | N32: Help begin of year storage
A33: Powell | C33: =IF(C$28<>"",IF(COLUMN(C27)=COLUMN($C27),$B$19,#REF!),"") -> 7.2 | D33: =C33 -> 7.2 | E33: =D33 -> 7.2 | F33: =E33 -> 7.2 | G33: =F33 -> 7.2 | H33: =G33 -> 7.2 | I33: =H33 -> 7.2 | J33: =I33 -> 7.2 | K33: =J33 -> 7.2 | L33: =K33 -> 7.2
A34: Mead | C34: =IF(C$28<>"",IF(COLUMN(C28)=COLUMN($C28),$C$19,#REF!),"") -> 9 | D34: =C34 -> 9 | E34: =D34 -> 9 | F34: =E34 -> 9 | G34: =F34 -> 9 | H34: =G34 -> 9 | I34: =H34 -> 9 | J34: =I34 -> 9 | K34: =J34 -> 9 | L34: =K34 -> 9
A35: Shared, Reserve storage | C35: =SUM(B21:C21) -> #REF! | D35: =C35 -> #REF! | E35: =D35 -> #REF! | F35: =E35 -> #REF! | G35: =F35 -> #REF! | H35: =G35 -> #REF! | I35: =H35 -> #REF! | J35: =I35 -> #REF! | K35: =J35 -> #REF! | L35: =K35 -> #REF!
A36: Calculate Powell + Mead Evaporation | C36: =IF(C$28<>"",VLOOKUP(C33*1000000,#REF!,3)*$B$18/1000000 + VLOOKUP(C34*1000000,'Mead-Elevation-Area'!$B$5:$D$676,3)*$C$18/1000000,"") -> #REF! | D36: =IF(D$28<>"",VLOOKUP(D33*1000000,#REF!,3)*$B$18/1000000 + VLOOKUP(D34*1000000,'Mead-Elevation-Area'!$B$5:$D$676,3)*$C$18/1000000,"") -> #REF! | E36: =IF(E$28<>"",VLOOKUP(E33*1000000,#REF!,3)*$B$18/1000000 + VLOOKUP(E34*1000000,'Mead-Elevation-Area'!$B$5:$D$676,3)*$C$18/1000000,"") -> #REF! | F36: =IF(F$28<>"",VLOOKUP(F33*1000000,#REF!,3)*$B$18/1000000 + VLOOKUP(F34*1000000,'Mead-Elevation-Area'!$B$5:$D$676,3)*$C$18/1000000,"") -> #REF! | G36: =IF(G$28<>"",VLOOKUP(G33*1000000,#REF!,3)*$B$18/1000000 + VLOOKUP(G34*1000000,'Mead-Elevation-Area'!$B$5:$D$676,3)*$C$18/1000000,"") -> #REF! | H36: =IF(H$28<>"",VLOOKUP(H33*1000000,#REF!,3)*$B$18/1000000 + VLOOKUP(H34*1000000,'Mead-Elevation-Area'!$B$5:$D$676,3)*$C$18/1000000,"") -> #REF! | I36: =IF(I$28<>"",VLOOKUP(I33*1000000,#REF!,3)*$B$18/1000000 + VLOOKUP(I34*1000000,'Mead-Elevation-Area'!$B$5:$D$676,3)*$C$18/1000000,"") -> #REF! | J36: =IF(J$28<>"",VLOOKUP(J33*1000000,#REF!,3)*$B$18/1000000 + VLOOKUP(J34*1000000,'Mead-Elevation-Area'!$B$5:$D$676,3)*$C$18/1000000,"") -> #REF! | ... L36: =IF(L$28<>"",VLOOKUP(L33*1000000,#REF!,3)*$B$18/1000000 + VLOOKUP(L34*1000000,'Mead-Elevation-Area'!$B$5:$D$676,3)*$C$18/1000000,"") -> #REF! | N36: Help Powell + Mead evaporation
A37: =IF(A10="",""," "&A10&" Share") -> Shared, Reserve Share | C37: =IF(OR(C$28="",$A37=""),"",C$36*C35/SUM(C33:C34)) -> #REF! | D37: =IF(OR(D$28="",$A37=""),"",D$36*D35/SUM(D33:D34)) -> #REF! | E37: =IF(OR(E$28="",$A37=""),"",E$36*E35/SUM(E33:E34)) -> #REF! | F37: =IF(OR(F$28="",$A37=""),"",F$36*F35/SUM(F33:F34)) -> #REF! | G37: =IF(OR(G$28="",$A37=""),"",G$36*G35/SUM(G33:G34)) -> #REF! | H37: =IF(OR(H$28="",$A37=""),"",H$36*H35/SUM(H33:H34)) -> #REF! | I37: =IF(OR(I$28="",$A37=""),"",I$36*I35/SUM(I33:I34)) -> #REF! | J37: =IF(OR(J$28="",$A37=""),"",J$36*J35/SUM(J33:J34)) -> #REF! | ... L37: =IF(OR(L$28="",$A37=""),"",L$36*L35/SUM(L33:L34)) -> #REF!
A38: Calculate Mexico Water Allocation | C38: =IF(C$28<>"",1.5-0.21/9/2-VLOOKUP(C34,MandatoryConservation!$C$5:$P$13,13)-C31*(1.5/8.7),"") -> 1.3048851 | D38: =IF(D$28<>"",1.5-0.21/9/2-VLOOKUP(D34,MandatoryConservation!$C$5:$P$13,13)-D31*(1.5/8.7),"") -> 1.3048851 | E38: =IF(E$28<>"",1.5-0.21/9/2-VLOOKUP(E34,MandatoryConservation!$C$5:$P$13,13)-E31*(1.5/8.7),"") -> 1.3048851 | F38: =IF(F$28<>"",1.5-0.21/9/2-VLOOKUP(F34,MandatoryConservation!$C$5:$P$13,13)-F31*(1.5/8.7),"") -> 1.3048851 | G38: =IF(G$28<>"",1.5-0.21/9/2-VLOOKUP(G34,MandatoryConservation!$C$5:$P$13,13)-G31*(1.5/8.7),"") -> 1.3048851 | H38: =IF(H$28<>"",1.5-0.21/9/2-VLOOKUP(H34,MandatoryConservation!$C$5:$P$13,13)-H31*(1.5/8.7),"") -> 1.3048851 | I38: =IF(I$28<>"",1.5-0.21/9/2-VLOOKUP(I34,MandatoryConservation!$C$5:$P$13,13)-I31*(1.5/8.7),"") -> 1.3048851 | J38: =IF(J$28<>"",1.5-0.21/9/2-VLOOKUP(J34,MandatoryConservation!$C$5:$P$13,13)-J31*(1.5/8.7),"") -> 1.3048851 | ... L38: =IF(L$28<>"",1.5-0.21/9/2-VLOOKUP(L34,MandatoryConservation!$C$5:$P$13,13)-L31*(1.5/8.7),"") -> 1.3048851 | M38: 16 | N38: Help Mexico water allocation
A39: 4. Split combined natural inflow among parties | C39: =IF(C28="","",SUM(C28:C30)) -> 0 | D39: =IF(D28="","",SUM(D28:D30)) -> 0.6 | E39: =IF(E28="","",SUM(E28:E30)) -> 1.2 | F39: =IF(F28="","",SUM(F28:F30)) -> 3.1 | G39: =IF(G28="","",SUM(G28:G30)) -> 4.5 | H39: =IF(H28="","",SUM(H28:H30)) -> 7 | I39: =IF(I28="","",SUM(I28:I30)) -> 9 | J39: =IF(J28="","",SUM(J28:J30)) -> 12.26 | ... L39: =IF(L28="","",SUM(L28:L30)) -> 17 | M39: =Master!C52 -> 3.8 | N39: Help split combined natural inflow
A40: =IF(A5="",""," To "&A5) -> To Upper Basin | B40: 1922+Remain | C40: =IF(OR(C$28="",$A41=""),"",MAX(0,C39-SUM(C41:C46))) -> #REF! | D40: =IF(OR(D$28="",$A41=""),"",MAX(0,D39-SUM(D41:D46))) -> #REF! | E40: =IF(OR(E$28="",$A41=""),"",MAX(0,E39-SUM(E41:E46))) -> #REF! | F40: =IF(OR(F$28="",$A41=""),"",MAX(0,F39-SUM(F41:F46))) -> #REF! | G40: =IF(OR(G$28="",$A41=""),"",MAX(0,G39-SUM(G41:G46))) -> #REF! | H40: =IF(OR(H$28="",$A41=""),"",MAX(0,H39-SUM(H41:H46))) -> #REF! | I40: =IF(OR(I$28="",$A41=""),"",MAX(0,I39-SUM(I41:I46))) -> #REF! | J40: =IF(OR(J$28="",$A41=""),"",MAX(0,J39-SUM(J41:J46))) -> #REF! | ... L40: =IF(OR(L$28="",$A41=""),"",MAX(0,L39-SUM(L41:L46))) -> #REF! | M40: =Master!C53 -> 0.36412144
A41: =IF(A6="",""," To "&A6) -> To Lower Basin | B41: =7.5-IF($A$9="",0,0.95)-IF(C31="",0.6,C31)*IF($A$9="",(7.2/8.7),(7.2-0.95)/8.7)-B43/2 -> 6.1111877 | C41: =IF(OR(C$28="",$A41=""),"",IF(C39<=SUM(C42:C46),0,IF(C39<=SUM(C42:C46)+2*$B$25,(C39-SUM(C42:C46))/2,IF(C39<=SUM(C42:C46)+2*$B$25+$B$41-$B$25,C39-SUM(C42:C46)-$B$25,$B$41)))) -> #REF! | D41: =IF(OR(D$28="",$A41=""),"",IF(D39<=SUM(D42:D46),0,IF(D39<=SUM(D42:D46)+2*$B$25,(D39-SUM(D42:D46))/2,IF(D39<=SUM(D42:D46)+2*$B$25+$B$41-$B$25,D39-SUM(D42:D46)-$B$25,$B$41)))) -> #REF! | E41: =IF(OR(E$28="",$A41=""),"",IF(E39<=SUM(E42:E46),0,IF(E39<=SUM(E42:E46)+2*$B$25,(E39-SUM(E42:E46))/2,IF(E39<=SUM(E42:E46)+2*$B$25+$B$41-$B$25,E39-SUM(E42:E46)-$B$25,$B$41)))) -> #REF! | F41: =IF(OR(F$28="",$A41=""),"",IF(F39<=SUM(F42:F46),0,IF(F39<=SUM(F42:F46)+2*$B$25,(F39-SUM(F42:F46))/2,IF(F39<=SUM(F42:F46)+2*$B$25+$B$41-$B$25,F39-SUM(F42:F46)-$B$25,$B$41)))) -> #REF! | G41: =IF(OR(G$28="",$A41=""),"",IF(G39<=SUM(G42:G46),0,IF(G39<=SUM(G42:G46)+2*$B$25,(G39-SUM(G42:G46))/2,IF(G39<=SUM(G42:G46)+2*$B$25+$B$41-$B$25,G39-SUM(G42:G46)-$B$25,$B$41)))) -> #REF! | H41: =IF(OR(H$28="",$A41=""),"",IF(H39<=SUM(H42:H46),0,IF(H39<=SUM(H42:H46)+2*$B$25,(H39-SUM(H42:H46))/2,IF(H39<=SUM(H42:H46)+2*$B$25+$B$41-$B$25,H39-SUM(H42:H46)-$B$25,$B$41)))) -> #REF! | I41: =IF(OR(I$28="",$A41=""),"",IF(I39<=SUM(I42:I46),0,IF(I39<=SUM(I42:I46)+2*$B$25,(I39-SUM(I42:I46))/2,IF(I39<=SUM(I42:I46)+2*$B$25+$B$41-$B$25,I39-SUM(I42:I46)-$B$25,$B$41)))) -> #REF! | J41: =IF(OR(J$28="",$A41=""),"",IF(J39<=SUM(J42:J46),0,IF(J39<=SUM(J42:J46)+2*$B$25,(J39-SUM(J42:J46))/2,IF(J39<=SUM(J42:J46)+2*$B$25+$B$41-$B$25,J39-SUM(J42:J46)-$B$25,$B$41)))) -> #REF! | ... L41: =IF(OR(L$28="",$A41=""),"",IF(L39<=SUM(L42:L46),0,IF(L39<=SUM(L42:L46)+2*$B$25,(L39-SUM(L42:L46))/2,IF(L39<=SUM(L42:L46)+2*$B$25+$B$41-$B$25,L39-SUM(L42:L46)-$B$25,$B$41)))) -> #REF! | M41: =Master!C55 -> 1.7039736
A42: =IF(A7="",""," To "&A7) -> To Mexico | B42: Row 38 | C42: =IF(OR(C$28="",$A42=""),"",MIN(C38,C$39-SUM(C43:C46))) -> #REF! | D42: =IF(OR(D$28="",$A42=""),"",MIN(D38,D$39-SUM(D43:D46))) -> #REF! | E42: =IF(OR(E$28="",$A42=""),"",MIN(E38,E$39-SUM(E43:E46))) -> #REF! | F42: =IF(OR(F$28="",$A42=""),"",MIN(F38,F$39-SUM(F43:F46))) -> #REF! | G42: =IF(OR(G$28="",$A42=""),"",MIN(G38,G$39-SUM(G43:G46))) -> #REF! | H42: =IF(OR(H$28="",$A42=""),"",MIN(H38,H$39-SUM(H43:H46))) -> #REF! | I42: =IF(OR(I$28="",$A42=""),"",MIN(I38,I$39-SUM(I43:I46))) -> #REF! | J42: =IF(OR(J$28="",$A42=""),"",MIN(J38,J$39-SUM(J43:J46))) -> #REF! | ... L42: =IF(OR(L$28="",$A42=""),"",MIN(L38,L$39-SUM(L43:L46))) -> #REF! | M42: =Master!C56 -> 0.68600217
A43: =IF(A8="",""," To "&A8) -> To Colorado River Delta | B43: =0.21/9*(2/3) -> 0.015555556 | C43: =IF(OR(C$28="",$A43=""),"",MIN($B43,C$39-SUM(C44:C46))) -> #REF! | D43: =IF(OR(D$28="",$A43=""),"",MIN($B43,D$39-SUM(D44:D46))) -> #REF! | E43: =IF(OR(E$28="",$A43=""),"",MIN($B43,E$39-SUM(E44:E46))) -> #REF! | F43: =IF(OR(F$28="",$A43=""),"",MIN($B43,F$39-SUM(F44:F46))) -> #REF! | G43: =IF(OR(G$28="",$A43=""),"",MIN($B43,G$39-SUM(G44:G46))) -> #REF! | H43: =IF(OR(H$28="",$A43=""),"",MIN($B43,H$39-SUM(H44:H46))) -> #REF! | I43: =IF(OR(I$28="",$A43=""),"",MIN($B43,I$39-SUM(I44:I46))) -> #REF! | J43: =IF(OR(J$28="",$A43=""),"",MIN($B43,J$39-SUM(J44:J46))) -> #REF! | ... L43: =IF(OR(L$28="",$A43=""),"",MIN($B43,L$39-SUM(L44:L46))) -> #REF! | M43: =Master!C57 -> 0.10974425
...

Sheet MandatoryConservation
A1: Mandatory Cutbacks according to 2007 Interim Guidelines, 2019 Drought Contingency Plan, and Minutes 319 and 323
D3: 2007 Interim Guidelines | F3: 2019 Drought Contingency Plan | I3: Combined | M3: Mexico
A4: Mead Elev (ft) | B4: Mead Vol (maf) | C4: Mead Vol offset (maf) | D4: AZ (taf/year) | E4: NV (taf/year) | F4: AZ (taf/year) | G4: NV (taf/year) | H4: CA (taf/year) | I4: AZ (taf/year) | J4: NV (taf/year) | K4: CA (taf/year) | L4: Lower Basin Cutback (maf/year) | M4: MX Cutback Minute 319 (taf/year) | N4: MX Cutback Minute 323 (taf/year) | O4: MX Cutback Total (maf/year) | P4: Total Cutback (maf/year)
A5: 1025 | B5: 5.981122 | C5: 0 | D5: 480 | E5: 20 | F5: 240 | G5: 10 | H5: 350 | I5: =SUM(D5,F5) -> 720 | J5: =SUM(E5,G5) -> 30 | K5: =H5 -> 350 | L5: =SUM(I5:K5)/1000 -> 1.1 | M5: 125 | N5: 150 | O5: =SUM(M5:N5)/1000 -> 0.275 | P5: =SUM(L5,O5) -> 1.375
A6: 1030 | B6: 6.305377 | C6: =B5 -> 5.981122 | D6: 400 | E6: 17 | F6: 240 | G6: 10 | H6: 350 | I6: =SUM(D6,F6) -> 640 | J6: =SUM(E6,G6) -> 27 | K6: =H6 -> 350 | L6: =SUM(I6:K6)/1000 -> 1.017 | M6: 70 | N6: 101 | O6: =SUM(M6:N6)/1000 -> 0.171 | P6: =SUM(L6,O6) -> 1.188
A7: 1035 | B7: 6.637508 | C7: =B6 -> 6.305377 | D7: 400 | E7: 17 | F7: 240 | G7: 10 | H7: 300 | I7: =SUM(D7,F7) -> 640 | J7: =SUM(E7,G7) -> 27 | K7: =H7 -> 300 | L7: =SUM(I7:K7)/1000 -> 0.967 | M7: 70 | N7: 92 | O7: =SUM(M7:N7)/1000 -> 0.162 | P7: =SUM(L7,O7) -> 1.129
A8: 1040 | B8: 6.977665 | C8: =B7 -> 6.637508 | D8: 400 | E8: 17 | F8: 240 | G8: 10 | H8: 250 | I8: =SUM(D8,F8) -> 640 | J8: =SUM(E8,G8) -> 27 | K8: =H8 -> 250 | L8: =SUM(I8:K8)/1000 -> 0.917 | M8: 70 | N8: 84 | O8: =SUM(M8:N8)/1000 -> 0.154 | P8: =SUM(L8,O8) -> 1.071
A9: 1045 | B9: 7.326052 | C9: =B8 -> 6.977665 | D9: 400 | E9: 17 | F9: 240 | G9: 10 | H9: 200 | I9: =SUM(D9,F9) -> 640 | J9: =SUM(E9,G9) -> 27 | K9: =H9 -> 200 | L9: =SUM(I9:K9)/1000 -> 0.867 | M9: 70 | N9: 76 | O9: =SUM(M9:N9)/1000 -> 0.146 | P9: =SUM(L9,O9) -> 1.013
A10: 1050 | B10: 7.682878 | C10: =B9 -> 7.326052 | D10: 400 | E10: 17 | F10: 192 | G10: 8 | H10: 0 | I10: =SUM(D10,F10) -> 592 | J10: =SUM(E10,G10) -> 25 | K10: =H10 -> 0 | L10: =SUM(I10:K10)/1000 -> 0.617 | M10: 70 | N10: 34 | O10: =SUM(M10:N10)/1000 -> 0.104 | P10: =SUM(L10,O10) -> 0.721
A11: 1075 | B11: 9.600988 | C11: =B10 -> 7.682878 | D11: 320 | E11: 13 | F11: 192 | G11: 8 | H11: 0 | I11: =SUM(D11,F11) -> 512 | J11: =SUM(E11,G11) -> 21 | K11: =H11 -> 0 | L11: =SUM(I11:K11)/1000 -> 0.533 | M11: 50 | N11: 30 | O11: =SUM(M11:N11)/1000 -> 0.08 | P11: =SUM(L11,O11) -> 0.613
A12: 1090 | B12: 10.857008 | C12: =B11 -> 9.600988 | D12: 0 | E12: 0 | F12: 192 | G12: 8 | H12: 0 | I12: =SUM(D12,F12) -> 192 | J12: =SUM(E12,G12) -> 8 | K12: =H12 -> 0 | L12: =SUM(I12:K12)/1000 -> 0.2 | M12: 0 | N12: 41 | O12: =SUM(M12:N12)/1000 -> 0.041 | P12: =SUM(L12,O12) -> 0.241
A13: 1090.1 | B13: 10.9 | C13: =B12 -> 10.857008 | D13: 0 | E13: 0 | F13: 0 | G13: 0 | H13: 0 | I13: =SUM(D13,F13) -> 0 | J13: =SUM(E13,G13) -> 0 | K13: =H13 -> 0 | L13: =SUM(I13:K13)/1000 -> 0 | M13: 0 | N13: 0 | O13: =SUM(M13:N13)/1000 -> 0 | P13: =SUM(L13,O13) -> 0
A16: Data from Wheeler et al (2021), Table 2.1
A17: 1091
A18: 1090 | D18: 0 | E18: 0 | F18: 192 | G18: 8 | H18: 0 | I18: =SUM(D18,F18) -> 192 | J18: =SUM(E18,G18) -> 8 | K18: =H18 -> 0 | L18: =SUM(I18:K18)/1000 -> 0.2 | M18: 0 | N18: 41 | O18: =SUM(M18:N18)/1000 -> 0.041 | P18: =SUM(L18,O18) -> 0.241
A19: 1075 | D19: 320 | E19: 13 | F19: 192 | G19: 8 | H19: 0 | I19: =SUM(D19,F19) -> 512 | J19: =SUM(E19,G19) -> 21 | K19: =H19 -> 0 | L19: =SUM(I19:K19)/1000 -> 0.533 | M19: 50 | N19: 30 | O19: =SUM(M19:N19)/1000 -> 0.08 | P19: =SUM(L19,O19) -> 0.613
A20: 1050 | D20: 400 | E20: 17 | F20: 192 | G20: 8 | H20: 0 | I20: =SUM(D20,F20) -> 592 | J20: =SUM(E20,G20) -> 25 | K20: =H20 -> 0 | L20: =SUM(I20:K20)/1000 -> 0.617 | M20: 70 | N20: 34 | O20: =SUM(M20:N20)/1000 -> 0.104 | P20: =SUM(L20,O20) -> 0.721
A21: 1045 | D21: 400 | E21: 17 | F21: 240 | G21: 10 | H21: 200 | I21: =SUM(D21,F21) -> 640 | J21: =SUM(E21,G21) -> 27 | K21: =H21 -> 200 | L21: =SUM(I21:K21)/1000 -> 0.867 | M21: 70 | N21: 76 | O21: =SUM(M21:N21)/1000 -> 0.146 | P21: =SUM(L21,O21) -> 1.013
A22: 1040 | D22: 400 | E22: 17 | F22: 240 | G22: 10 | H22: 250 | I22: =SUM(D22,F22) -> 640 | J22: =SUM(E22,G22) -> 27 | K22: =H22 -> 250 | L22: =SUM(I22:K22)/1000 -> 0.917 | M22: 70 | N22: 84 | O22: =SUM(M22:N22)/1000 -> 0.154 | P22: =SUM(L22,O22) -> 1.071
A23: 1035 | D23: 400 | E23: 17 | F23: 240 | G23: 10 | H23: 300 | I23: =SUM(D23,F23) -> 640 | J23: =SUM(E23,G23) -> 27 | K23: =H23 -> 300 | L23: =SUM(I23:K23)/1000 -> 0.967 | M23: 70 | N23: 92 | O23: =SUM(M23:N23)/1000 -> 0.162 | P23: =SUM(L23,O23) -> 1.129
A24: 1030 | D24: 400 | E24: 17 | F24: 240 | G24: 10 | H24: 350 | I24: =SUM(D24,F24) -> 640 | J24: =SUM(E24,G24) -> 27 | K24: =H24 -> 350 | L24: =SUM(I24:K24)/1000 -> 1.017 | M24: 70 | N24: 101 | O24: =SUM(M24:N24)/1000 -> 0.171 | P24: =SUM(L24,O24) -> 1.188
A25: 1025 | D25: 480 | E25: 20 | F25: 240 | G25: 10 | H25: 350 | I25: =SUM(D25,F25) -> 720 | J25: =SUM(E25,G25) -> 30 | K25: =H25 -> 350 | L25: =SUM(I25:K25)/1000 -> 1.1 | M25: 125 | N25: 150 | O25: =SUM(M25:N25)/1000 -> 0.275 | P25: =SUM(L25,O25) -> 1.375
A26: 955

Sheet PowellReleaseTemperature
A1: Effect of water storage in Lake Powell on release temperatures and Grand Canyon Fish
A2: From Wheeler et al (2021), p.48, Sidebar #1. https://qcnr.usu.edu/coloradoriver/files/WhitePaper6.pdf
I3: Release through Turbines (elevation 3,490 feet).
A4: Summer Elevation (feet) | B4: Release Temperature (oC) | C4: Outlet | D4: Ecological interpretation | E4: Native fish phrase | F4: Tailwater trout phrase | G4: Storage Volume (MAF)
A5: =#REF! -> #REF! | B5: > 18 | C5: River | D5: =D7 -> Highest uncertainty for native fish. Also represent a substantial risk to the tailwater trout fishery, as sustained temperatures of 19oC or higher are unsuitable for trout. | E5: Highly uncertain | F5: Unsuitable | G5: =VLOOKUP(A5,#REF!,2)/1000000 -> #REF!
A6: 3425 | B6: =B7 -> > 18 | C6: River | D6: =D7 -> Highest uncertainty for native fish. Also represent a substantial risk to the tailwater trout fishery, as sustained temperatures of 19oC or higher are unsuitable for trout. | E6: =E5 -> Highly uncertain | F6: Unsuitable | G6: =VLOOKUP(A6,#REF!,2)/1000000 -> #REF!
A7: 3490 | B7: > 18 | C7: Penstock | D7: Highest uncertainty for native fish. Also represent a substantial risk to the tailwater trout fishery, as sustained temperatures of 19oC or higher are unsuitable for trout. | E7: =E6 -> Highly uncertain | F7: Unsuitable | G7: =VLOOKUP(A7,#REF!,2)/1000000 -> #REF!
A8: 3525 | B8: < 18 | C8: Penstock | D8: Outcomes are highly uncertain for native fish, as these temperatures have not been observed since the construction of the Glen Canyon Dam. Native fish may benefit, but they may also face invasion by warm water non-natives from Lake Mead. | E8: May benefit or face invasion | F8: Help grow + incubate | G8: =VLOOKUP(A8,#REF!,2)/1000000 -> #REF!
A9: 3600 | B9: < 15 | C9: Penstock | D9: Increased relative abundance of native fishes in western Grand Canyon, but other factors also likely contribute to these trends | E9: Increased relative abundance | F9: =F8 -> Help grow + incubate | G9: =VLOOKUP(A9,#REF!,2)/1000000 -> #REF!
A10: 3675 | B10: < 12 | C10: Penstock | D10: Important for many species’ growth, reproduction, and survival of early life stages. Temperatures below 12oC are within the range that have been observed in the past (Fig-ure 8.5), but these cold releases during the growing season have been associated with native fishes being predominantly pushed into tributary and downstream habitats. | E10: Help grow, reproduce, and survive | F10: Help all | G10: =VLOOKUP(A10,#REF!,2)/1000000 -> #REF!
A11: 3700 | B11: =B10 -> < 12 | C11: Penstock | D11: =D10 -> Important for many species’ growth, reproduction, and survival of early life stages. Temperatures below 12oC are within the range that have been observed in the past (Fig-ure 8.5), but these cold releases during the growing season have been associated with native fishes being predominantly pushed into tributary and downstream habitats. | E11: =E10 -> Help grow, reproduce, and survive | F11: Help all | G11: =VLOOKUP(A11,#REF!,2)/1000000 -> #REF!

Sheet Mead-Elevation-Area
A1: Lake Mead Elevation-Volume-Area Relationship
A2: (USBR 2017, CRSS Model)
C3: 2035000
A4: Elevation (ft) | B4: Live Storage (ac-ft) | C4: Total Storage (ac-ft) | D4: Area (acres) | E4: Row
A5: 895 | B5: 0 | C5: =B5+$C$3 -> 2035000 | D5: 30172 | E5: 1 | H5: =A5 -> 895
A6: 895.5 | B6: 15111 | C6: =B6+$C$3 -> 2050111 | D6: 30270 | E6: 2 | H6: =A6 -> 895.5
A7: 896 | B7: 30270 | C7: =B7+$C$3 -> 2065270 | D7: 30368 | E7: 3 | H7: =A7 -> 896
A8: 896.5 | B8: 45479 | C8: =B8+$C$3 -> 2080479 | D8: 30466 | E8: 4 | H8: =A8 -> 896.5
A9: 897 | B9: 60736 | C9: =B9+$C$3 -> 2095736 | D9: 30564 | E9: 5 | H9: =A9 -> 897
A10: 897.5 | B10: 76043 | C10: =B10+$C$3 -> 2111043 | D10: 30662 | E10: 6 | H10: =A10 -> 897.5
A11: 898 | B11: 91398 | C11: =B11+$C$3 -> 2126398 | D11: 30760 | E11: 7 | H11: =A11 -> 898
A12: 898.5 | B12: 106803 | C12: =B12+$C$3 -> 2141803 | D12: 30858 | E12: 8 | H12: =A12 -> 898.5
A13: 899 | B13: 122257 | C13: =B13+$C$3 -> 2157257 | D13: 30956 | E13: 9 | H13: =A13 -> 899
A14: 899.5 | B14: 137759 | C14: =B14+$C$3 -> 2172759 | D14: 31054 | E14: 10 | H14: =A14 -> 899.5
A15: 900 | B15: 153311 | C15: =B15+$C$3 -> 2188311 | D15: 31152 | E15: 11 | H15: =A15 -> 900
A16: 900.5 | B16: 168917 | C16: =B16+$C$3 -> 2203917 | D16: 31273 | E16: 12 | H16: =A16 -> 900.5
... A676: 1250 | B676: 30809525 | C676: =B676+$C$3 -> 32844525 | D676: 175800 | E676: 672 | H676: =A676 -> 1250

Sheet CellType
A1: Expands on Table in the master worksheet
A3: Cell Type | D3: Explanation
A4: Physical watershed data | D4: Flow and evaporation assumptions required by the model. Participants agree on this data and information.
A5: Individual decision | D5: A participant's individual choices such as strategy, conservation, consumption, and purchaces from the account.
A6: Joint decision | D6: Decisions participants make together such as the reservoir protection elevations, how to split existing storage and inflow among accounts, or how to split combined storage between Lake Powell and Lake Mead.
A7: Calculated cell | D7: Formula used to calculate cell such as reservoir evaporation or an account's available water.
A11: Physical watershed data
A12: Individual party decision
A13: Joint party decision
A14: Calculated cell

Sheet BasinConservationPrograms
A1: Colorado River Conservation Programs
A2: Program
A3: Program | B3: Years | C3: Volume (million acre-feet) | D3: Cost ($ per acre-foot) | E3: Compensation ($ million)
A4: Existing Programs
A5: System Conservation Pilot Programs
A6: Lower Basin | B6: 2015 to 2019 | C6: 0.175 | D6: $77 to $240 | E6: 29.8
A7: Upper Basin | B7: 2023 | C7: =(2517+4633+15091+15571)/1000000 -> 0.037812 | D7: $150 to $611 | E7: =0.992+1.205+5.344+8.335 -> 15.876
A8: Upper Basin | B8: 2015 to 2017 | C8: 0.022116 | D8: $161 to $670 | E8: 4.56
A9: Existing Programs
A10: Lake Mead Water Conservation Accounts | B10: 2007 to 2023 | C10: 4.1 | D10: None | E10: None
A11: Mandatory Conservation - Not ICS | B11: 2019 to 2023 | C11: 0.63121 | D11: None | E11: None
A12: Comparison Options
A13: Lower Basin agricultural value | B13: 2021 | C13: None yet | D13: $700 to $1,000 | E13: None yet
A14: Desalination at the Sea of Cortez | B14: 2021 | C14: None yet | D14: 2000 | E14: None yet
A15: 500+ Plan - Lower Basin | B15: 2021 to 2022 | C15: 1 | D15: 200 | E15: 200

Sheet LakeMeadInflowScenarios
A1: Scenarios of Extreme Lake Mead Inflow
A2: The annual Lake Mead inflow magnitude has been determined by using data from the data sheet, HydrologicScenarios (Salehabadi 2023). All Ensembles and traces were used in determining Lake Mead’s inflow. Using code written in Python, three consecutive smallest values in each trace were found.
A4: Ensemble | B4: # of Traces | C4: Minimum Summation of Ensemble | D4: Trace | E4: Position | F4: First | G4: Second | H4: Third | I4: Average
A5: CMIP5_LOCA | B5: 64 | C5: 0 | D5: 8 | E5: 122 | F5: 0 | G5: 0 | H5: 0 | I5: =AVERAGE(F5:H5) -> 0
A6: RCP_85_100 | B6: 112 | C6: 11.6 | D6: trace17 | E6: 81 | F6: 2.8 | G6: 4.7 | H6: 4.2 | I6: =AVERAGE(F6:H6) -> 3.9
A7: AR1 | B7: 100 | C7: 14.1 | D7: trace17 | E7: 13 | F7: 10 | G7: -1.3 | H7: 5.4 | I7: =AVERAGE(F7:H7) -> 4.7
A8: CMIP5_BCSD | B8: 97 | C8: 14.1 | D8: 65 | E8: 147 | F8: 3.8 | G8: 6.3 | H8: 4 | I8: =AVERAGE(F8:H8) -> 4.7 | J8: Chosen
A9: CMIP3 | B9: 112 | C9: 16.5 | D9: Trace55 | E9: 103 | F9: 5.9 | G9: 5.1 | H9: 5.5 | I9: =AVERAGE(F9:H9) -> 5.5 | J9: X
A10: Drought_Mid20th | B10: 100 | C10: 16.6 | D10: Trace33 | E10: 26 | F10: 5.5 | G10: 5.5 | H10: 5.5 | I10: =AVERAGE(F10:H10) -> 5.5
A11: RCP85_065 | B11: 112 | C11: 16.6 | D11: trace17 | E11: 81 | F11: 3.8 | G11: 6.6 | H11: 6.1 | I11: =AVERAGE(F11:H11) -> 5.5 | J11: X
A12: NPC_1988_2020 | B12: 100 | C12: 17.8 | D12: Trace1 | E12: 31 | F12: 5.9 | G12: 5.9 | H12: 5.9 | I12: =AVERAGE(F12:H12) -> 5.9
A13: Drought_Paleo | B13: 100 | C13: 18 | D13: Trace42 | E13: 18 | F13: 11 | G13: 5.6 | H13: 8.1 | I13: =AVERAGE(F13:H13) -> 8.2333333
A14: RCP45_100 | B14: 112 | C14: 19.3 | D14: trace17 | E14: 81 | F14: 4.4 | G14: 7.8 | H14: 7.2 | I14: =AVERAGE(F14:H14) -> 6.4666667
A15: Drought_Millennium | B15: 100 | C15: 20.4 | D15: Trace46 | E15: 48 | F15: 5.9 | G15: 5.9 | H15: 8.5 | I15: =AVERAGE(F15:H15) -> 6.7666667
A16: NPC_1906_2020 | B16: 100 | C16: 20.4 | D16: Trace18 | E16: 45 | F16: 8.3 | G16: 6.6 | H16: 5.5 | I16: =AVERAGE(F16:H16) -> 6.8
A17: NPC_2000_2020 | B17: 100 | C17: 20.5 | D17: Trace94 | E17: 2 | F17: 8.6 | G17: 5.9 | H17: 5.9 | I17: =AVERAGE(F17:H17) -> 6.8
A18: ISM_TRM17SK | B18: 1 | C18: 20.9 | D18: Trace1 | E18: 430 | F18: 6.4 | G18: 8.4 | H18: 6.1 | I18: =AVERAGE(F18:H18) -> 6.9666667
A19: TreeRingFlows | B19: 1 | C19: 20.9 | D19: Trace1 | E19: 430 | F19: 6.4 | G19: 8.4 | H19: 6.1 | I19: =AVERAGE(F19:H19) -> 6.9666667
A20: RCP45_065 | B20: 112 | C20: 21.7 | D20: trace17 | E20: 81 | F20: 4.9 | G20: 8.7 | H20: 8.1 | I20: =AVERAGE(F20:H20) -> 7.2333333
A21: RCP85_030 | B21: 112 | C21: 21.8 | D21: trace17 | E21: 81 | F21: 5 | G21: 8.7 | H21: 8.1 | I21: =AVERAGE(F21:H21) -> 7.2666667
A22: RCP45_030 | B22: 112 | C22: 24.2 | D22: trace18 | E22: 80 | F22: 5.5 | G22: 9.7 | H22: 9 | I22: =AVERAGE(F22:H22) -> 8.0666667
A23: Mill_5YrBlockRes | B23: 100 | C23: 24.8 | D23: Trace27 | E23: 5 | F23: 8.4 | G23: 5.9 | H23: 10.5 | I23: =AVERAGE(F23:H23) -> 8.2666667
... A26: ISM_StressTest | B26: 1 | C26: 26.1 | D26: Trace1 | E26: 15 | F26: 5.9 | G26: 10.5 | H26: 9.6 | I26: =AVERAGE(F26:H26) -> 8.6666667

Sheet DynamicPlotData
B1: Year 1 | C1: Year 2 | D1: Year 3 | E1: Year 4 | F1: Year 5
A2: Chosen Protection Elevation | B2: =Master!$C$20 -> 5.664593 | C2: =Master!$C$20 -> 5.664593 | D2: =Master!$C$20 -> 5.664593 | E2: =Master!$C$20 -> 5.664593 | F2: =Master!$C$20 -> 5.664593
A3: DCP Trigger | B3: 10.857008 | C3: 10.857008 | D3: 10.857008 | E3: 10.857008 | F3: 10.857008
A4: Min Power Pool | B4: 2.22317 | C4: 2.22317 | D4: 2.22317 | E4: 2.22317 | F4: 2.22317
A5: Final EIS Buffer Line
